<?xml version="1.0"?>
<robot name="drawer">
  <link name="base_link" />
  <link name="drawer_frame">
    <inertial>
      <mass value="5.0" />
      <origin xyz="0 0 0" />
      <inertia  ixx="0.000128" ixy="0.0"  ixz="0.0"  iyy="0.000128"  iyz="0.0" izz="0.000128" />
    </inertial>
    <visual>
      <geometry>
        <mesh filename="../meshes/drawer/visual/drawer_frame.dae"/>
      </geometry>
    </visual>
    <collision>
      <origin rpy="0 0 0" xyz="0 0.155 0.28"/>
      <geometry>
        <box size="0.04 0.31 0.04" />
      </geometry>
    </collision>
    <collision>
      <origin rpy="0 0 0" xyz="0 0.155 -0.28"/>
      <geometry>
        <box size="0.04 0.31 0.04" />
      </geometry>
    </collision>
    <collision>
      <origin rpy="0 0 0" xyz="-0.405 0.155 0.28"/>
      <geometry>
        <box size="0.04 0.31 0.04" />
      </geometry>
    </collision>
    <collision>
      <origin rpy="0 0 0" xyz="-0.405 0.155 -0.28"/>
      <geometry>
        <box size="0.04 0.31 0.04" />
      </geometry>
    </collision>
    <collision>
      <origin rpy="0 0 0" xyz="-0.2025 0.29 0"/>
      <geometry>
        <box size="0.445 0.04 0.6" />
      </geometry>
    </collision>
    <collision>
      <origin rpy="0 0 0" xyz="-0.2025 0.1275 -0.275"/>
      <geometry>
        <box size="0.4 0.026 0.02" />
      </geometry>
    </collision>
    <collision>
      <origin rpy="0 0 0" xyz="-0.2025 0.1275 0.275"/>
      <geometry>
        <box size="0.4 0.026 0.02" />
      </geometry>
    </collision>
  </link>
  <joint name="base_link_to_drawer_frame" type="fixed">
    <parent link="base_link"/>
    <child link="drawer_frame"/>
  </joint>
  <link name="drawer">
    <inertial>
      <mass value="0.75" />
      <origin xyz="0 0 0" />
      <inertia  ixx="0.000128" ixy="0.0"  ixz="0.0"  iyy="0.000128"  iyz="0.0" izz="0.000128" />
    </inertial>
    <visual>
      <geometry>
        <mesh filename="../meshes/drawer/visual/drawer.dae"/>
      </geometry>
    </visual>
    <collision>
      <origin rpy="0 0 0" xyz="0. 0.135 0."/>
      <geometry>
        <box size="0.03 0.25 0.5" />
      </geometry>
    </collision>
    <collision>
      <origin rpy="0 0 0" xyz="-0.3925 0.12 0."/>
      <geometry>
        <box size="0.015 0.22 0.5" />
      </geometry>
    </collision>
    <collision>
      <origin rpy="0 0 0" xyz="-0.2 0.0175 0."/>
      <geometry>
        <box size="0.4 0.015 0.5" />
      </geometry>
    </collision>
    <collision>
      <origin rpy="0 0 0" xyz="-0.2 0.12 -0.2425"/>
      <geometry>
        <box size="0.4 0.22 0.015" />
      </geometry>
    </collision>
    <collision>
      <origin rpy="0 0 0" xyz="-0.2 0.12 0.2425"/>
      <geometry>
        <box size="0.4 0.22 0.015" />
      </geometry>
    </collision>
    <collision>
      <origin rpy="0 0 0" xyz="0.1 0.135 0."/>
      <geometry>
        <cylinder length="0.4" radius="0.0125"/>
      </geometry>
    </collision>
    <collision>
      <origin rpy="0 1.571 0" xyz="0.05 0.135 0.15"/>
      <geometry>
        <cylinder length="0.1" radius="0.0075"/>
      </geometry>
    </collision>
    <collision>
      <origin rpy="0 1.571 0" xyz="0.05 0.135 -0.15"/>
      <geometry>
        <cylinder length="0.1" radius="0.0075"/>
      </geometry>
    </collision>
  </link>
  <joint name="drawer_frame_to_drawer" type="prismatic">
    <parent link="drawer_frame"/>
    <child link="drawer"/>
    <limit effort="330.0" lower="0.0" upper="0.35" velocity="2.09439510239"/>
    <origin rpy="0 0 0" xyz="0 0 0"/>
  </joint>
</robot>